Workbook

Sheet P2_Customers
A1: Customer ID | B1: Customer Name | C1: Region | D1: Segment | E1: City
A2: C001 | B2: Aarav Retail | C2: North | D2: Retail | E2: Hyderabad
A3: C002 | B3: BlueMart | C3: South | D3: Retail | E3: Chennai
A4: C003 | B4: Crest Foods | C4: West | D4: Wholesale | E4: Mumbai
A5: C004 | B5: Delta Stores | C5: North | D5: Retail | E5: Delhi
A6: C005 | B6: Elite Supplies | C6: South | D6: Wholesale | E6: Bengaluru
A7: C006 | B7: Fresh Basket | C7: East | D7: Retail | E7: Kolkata
A8: C007 | B8: Green Valley | C8: West | D8: Retail | E8: Pune
A9: C008 | B9: Horizon Cafe | C9: South | D9: Food Service | E9: Chennai
A10: C009 | B10: Ivy Traders | C10: North | D10: Wholesale | E10: Delhi
A11: C010 | B11: Jupiter Mart | C11: West | D11: Retail | E11: Pune
A12: C011 | B12: Kaveri Foods | C12: South | D12: Wholesale | E12: Hyderabad
... A22: C020 | B22: TrueValue | C22: East | D22: Wholesale | E22: Kolkata

Sheet P2_Sales
A1: Order ID | B1: Order Date | C1: Customer ID | D1: Product | E1: Category | F1: Region | G1: Units | H1: Unit Price | I1: Discount
A2: O1001 | B2: 46027 | C2: C001 | D2: Laptop Stand | E2: Electronics | F2: North | G2: 8 | H2: 1250 | I2: 0.05
A3: O1002 | B3: 46029 | C3: C003 | D3: Keyboard | E3: Electronics | F3: West | G3: 15 | H3: 1800 | I3: 0.1
A4: O1003 | B4: 46031 | C4: C002 | D4: Office Chair | E4: Furniture | F4: South | G4: 6 | H4: 7200 | I4: 0.08
A5: O1004 | B5: 46034 | C5: C005 | D5: Monitor | E5: Electronics | F5: South | G5: 9 | H5: 14500 | I5: 0.12
A6: O1005 | B6: 46037 | C6: C004 | D6: Desk | E6: Furniture | F6: North | G6: 4 | H6: 12000 | I6: 0.05
A7: O1006 | B7: 46040 | C7: C006 | D7: Mouse | E7: Electronics | F7: East | G7: 25 | H7: 750 | I7: 0
A8: O1007 | B8: 46042 | C8: C007 | D8: Webcam | E8: Electronics | F8: West | G8: 12 | H8: 3200 | I8: 0.07
A9: O1008 | B9: 46045 | C9: C008 | D9: Headset | E9: Electronics | F9: South | G9: 18 | H9: 2100 | I9: 0.05
A10: O1009 | B10: 46048 | C10: C009 | D10: Printer | E10: Electronics | F10: North | G10: 5 | H10: 9800 | I10: 0.1
A11: O1010 | B11: 46050 | C11: C010 | D11: Desk Lamp | E11: Furniture | F11: West | G11: 14 | H11: 1650 | I11: 0.03
A12: O1011 | B12: 46055 | C12: C011 | D12: Office Chair | E12: Furniture | F12: South | G12: 7 | H12: 7200 | I12: 0.08
A13: O1012 | B13: 46058 | C13: C012 | D13: Keyboard | E13: Electronics | F13: East | G13: 20 | H13: 1800 | I13: 0.06
... A41: O1040 | B41: 46141 | C41: C020 | D41: Webcam | E41: Electronics | F41: East | G41: 14 | H41: 3200 | I41: 0.06

Sheet customers_copy
A1: Customer ID | B1: Customer Name | C1: Region | D1: Segment | E1: City
A2: C001 | B2: Aarav Retail | C2: North | D2: Retail | E2: Hyderabad
A3: C002 | B3: BlueMart | C3: South | D3: Retail | E3: Chennai
A4: C003 | B4: Crest Foods | C4: West | D4: Wholesale | E4: Mumbai
A5: C004 | B5: Delta Stores | C5: North | D5: Retail | E5: Delhi
A6: C005 | B6: Elite Supplies | C6: South | D6: Wholesale | E6: Bengaluru
A7: C006 | B7: Fresh Basket | C7: East | D7: Retail | E7: Kolkata
A8: C007 | B8: Green Valley | C8: West | D8: Retail | E8: Pune
A9: C008 | B9: Horizon Cafe | C9: South | D9: Food Service | E9: Chennai
A10: C009 | B10: Ivy Traders | C10: North | D10: Wholesale | E10: Delhi
A11: C010 | B11: Jupiter Mart | C11: West | D11: Retail | E11: Pune
A12: C011 | B12: Kaveri Foods | C12: South | D12: Wholesale | E12: Hyderabad
... A22: C020 | B22: TrueValue | C22: East | D22: Wholesale | E22: Kolkata

Sheet sales_copy
A1: Order ID | B1: Order Date | C1: Customer ID | D1: Product | E1: Category | F1: Region | G1: Units | H1: Unit Price | I1: Discount
A2: O1001 | B2: 46027 | C2: C001 | D2: Laptop Stand | E2: Electronics | F2: North | G2: 8 | H2: 1250 | I2: 0.05
A3: O1002 | B3: 46029 | C3: C003 | D3: Keyboard | E3: Electronics | F3: West | G3: 15 | H3: 1800 | I3: 0.1
A4: O1003 | B4: 46031 | C4: C002 | D4: Office Chair | E4: Furniture | F4: South | G4: 6 | H4: 7200 | I4: 0.08
A5: O1004 | B5: 46034 | C5: C005 | D5: Monitor | E5: Electronics | F5: South | G5: 9 | H5: 14500 | I5: 0.12
A6: O1005 | B6: 46037 | C6: C004 | D6: Desk | E6: Furniture | F6: North | G6: 4 | H6: 12000 | I6: 0.05
A7: O1006 | B7: 46040 | C7: C006 | D7: Mouse | E7: Electronics | F7: East | G7: 25 | H7: 750 | I7: 0
A8: O1007 | B8: 46042 | C8: C007 | D8: Webcam | E8: Electronics | F8: West | G8: 12 | H8: 3200 | I8: 0.07
A9: O1008 | B9: 46045 | C9: C008 | D9: Headset | E9: Electronics | F9: South | G9: 18 | H9: 2100 | I9: 0.05
A10: O1009 | B10: 46048 | C10: C009 | D10: Printer | E10: Electronics | F10: North | G10: 5 | H10: 9800 | I10: 0.1
A11: O1010 | B11: 46050 | C11: C010 | D11: Desk Lamp | E11: Furniture | F11: West | G11: 14 | H11: 1650 | I11: 0.03
A12: O1011 | B12: 46055 | C12: C011 | D12: Office Chair | E12: Furniture | F12: South | G12: 7 | H12: 7200 | I12: 0.08
A13: O1012 | B13: 46058 | C13: C012 | D13: Keyboard | E13: Electronics | F13: East | G13: 20 | H13: 1800 | I13: 0.06
... A41: O1040 | B41: 46141 | C41: C020 | D41: Webcam | E41: Electronics | F41: East | G41: 14 | H41: 3200 | I41: 0.06

Sheet P2_Tasks
A1: Task # | B1: Task
A2: 1 | B2: On the customer table, use Remove Duplicates to remove the intentional duplicate C020. Make a copy first.
A3: 2 | B3: Create Sales Amount = Units × Unit Price × (1 - Discount). Use Autofill.
A4: 3 | B4: Create Discount Amount = Units × Unit Price × Discount.
A5: 4 | B5: Use COUNT, COUNTA and COUNTBLANK on suitable ranges.
A6: 5 | B6: Use VLOOKUP with exact match to bring Customer Name into Sales using Customer ID.
A7: 6 | B7: Use VLOOKUP with exact match to bring Customer Segment into Sales.
A8: 7 | B8: Create a horizontal Sales Band table: 0=Low, 10000=Medium, 25000=High, 50000=Very High. Use HLOOKUP with approximate match on selected Sales Amounts.
A9: 8 | B9: Explain exact-match versus approximate-match lookup in your own words.
A10: 9 | B10: Write an XLOOKUP formula as a concept for returning Customer Name from Customer ID. Do not worry if Excel 2019 cannot execute it.
A11: 10 | B11: Use Data Validation to create an Order Status dropdown: Pending, Shipped, Delivered, Cancelled. Apply it to at least 10 practice cells.
A12: 12 | B12: Sort Sales Amount largest to smallest and filter to Electronics.
A13: 13 | B13: Use Conditional Formatting to highlight Sales Amount above ₹50,000 and Discount >= 10%.
... A24: 24 | B24: Create a combo chart with monthly Sales Amount as columns and Average Discount as a line on the secondary Y-axis.

Sheet sales_answers
A1: Order ID | B1: Order Date | C1: Customer ID | D1: Product | E1: Category | F1: Region | G1: Units | H1: Unit Price | I1: Discount | J1: sales_amount | K1: discount_amount | L1: customer name | M1: segment
A2: O1001 | B2: 46027 | C2: C001 | D2: Laptop Stand | E2: Electronics | F2: North | G2: 8 | H2: 1250 | I2: 0.05 | J2: =(G2*H2)*(1-I2) -> 9500 | K2: =G2*H2*I2 -> 500 | L2: =VLOOKUP(C2,customers_copy!$A$1:$E$22,2,0) -> Aarav Retail | M2: =VLOOKUP(C2,customers_copy!$A$1:$E$22,4,0) -> Retail
A3: O1002 | B3: 46029 | C3: C003 | D3: Keyboard | E3: Electronics | F3: West | G3: 15 | H3: 1800 | I3: 0.1 | J3: =(G3*H3)*(1-I3) -> 24300 | K3: =G3*H3*I3 -> 2700 | L3: =VLOOKUP(C3,customers_copy!$A$1:$E$22,2,0) -> Crest Foods | M3: =VLOOKUP(C3,customers_copy!$A$1:$E$22,4,0) -> Wholesale | T3: count | U3: =COUNT(H2:H41) -> 40
A4: O1003 | B4: 46031 | C4: C002 | D4: Office Chair | E4: Furniture | F4: South | G4: 6 | H4: 7200 | I4: 0.08 | J4: =(G4*H4)*(1-I4) -> 39744 | K4: =G4*H4*I4 -> 3456 | L4: =VLOOKUP(C4,customers_copy!$A$1:$E$22,2,0) -> BlueMart | M4: =VLOOKUP(C4,customers_copy!$A$1:$E$22,4,0) -> Retail | T4: counta | U4: =COUNTA(A2:A41) -> 40
A5: O1004 | B5: 46034 | C5: C005 | D5: Monitor | E5: Electronics | F5: South | G5: 9 | H5: 14500 | I5: 0.12 | J5: =(G5*H5)*(1-I5) -> 114840 | K5: =G5*H5*I5 -> 15660 | L5: =VLOOKUP(C5,customers_copy!$A$1:$E$22,2,0) -> Elite Supplies | M5: =VLOOKUP(C5,customers_copy!$A$1:$E$22,4,0) -> Wholesale | T5: COUNTBLANK | U5: =COUNTBLANK(V6:V20) -> 3 | V5: TEST RANGE FOR COUNT BLANK
A6: O1005 | B6: 46037 | C6: C004 | D6: Desk | E6: Furniture | F6: North | G6: 4 | H6: 12000 | I6: 0.05 | J6: =(G6*H6)*(1-I6) -> 45600 | K6: =G6*H6*I6 -> 2400 | L6: =VLOOKUP(C6,customers_copy!$A$1:$E$22,2,0) -> Delta Stores | M6: =VLOOKUP(C6,customers_copy!$A$1:$E$22,4,0) -> Retail | V6: 24300
A7: O1006 | B7: 46040 | C7: C006 | D7: Mouse | E7: Electronics | F7: East | G7: 25 | H7: 750 | I7: 0 | J7: =(G7*H7)*(1-I7) -> 18750 | K7: =G7*H7*I7 -> 0 | L7: =VLOOKUP(C7,customers_copy!$A$1:$E$22,2,0) -> Fresh Basket | M7: =VLOOKUP(C7,customers_copy!$A$1:$E$22,4,0) -> Retail | V7: 39744
A8: O1007 | B8: 46042 | C8: C007 | D8: Webcam | E8: Electronics | F8: West | G8: 12 | H8: 3200 | I8: 0.07 | J8: =(G8*H8)*(1-I8) -> 35712 | K8: =G8*H8*I8 -> 2688 | L8: =VLOOKUP(C8,customers_copy!$A$1:$E$22,2,0) -> Green Valley | M8: =VLOOKUP(C8,customers_copy!$A$1:$E$22,4,0) -> Retail | V8: 114840
A9: O1008 | B9: 46045 | C9: C008 | D9: Headset | E9: Electronics | F9: South | G9: 18 | H9: 2100 | I9: 0.05 | J9: =(G9*H9)*(1-I9) -> 35910 | K9: =G9*H9*I9 -> 1890 | L9: =VLOOKUP(C9,customers_copy!$A$1:$E$22,2,0) -> Horizon Cafe | M9: =VLOOKUP(C9,customers_copy!$A$1:$E$22,4,0) -> Food Service | V9: 45600
A10: O1009 | B10: 46048 | C10: C009 | D10: Printer | E10: Electronics | F10: North | G10: 5 | H10: 9800 | I10: 0.1 | J10: =(G10*H10)*(1-I10) -> 44100 | K10: =G10*H10*I10 -> 4900 | L10: =VLOOKUP(C10,customers_copy!$A$1:$E$22,2,0) -> Ivy Traders | M10: =VLOOKUP(C10,customers_copy!$A$1:$E$22,4,0) -> Wholesale
A11: O1010 | B11: 46050 | C11: C010 | D11: Desk Lamp | E11: Furniture | F11: West | G11: 14 | H11: 1650 | I11: 0.03 | J11: =(G11*H11)*(1-I11) -> 22407 | K11: =G11*H11*I11 -> 693 | L11: =VLOOKUP(C11,customers_copy!$A$1:$E$22,2,0) -> Jupiter Mart | M11: =VLOOKUP(C11,customers_copy!$A$1:$E$22,4,0) -> Retail | V11: 35712
A12: O1011 | B12: 46055 | C12: C011 | D12: Office Chair | E12: Furniture | F12: South | G12: 7 | H12: 7200 | I12: 0.08 | J12: =(G12*H12)*(1-I12) -> 46368 | K12: =G12*H12*I12 -> 4032 | L12: =VLOOKUP(C12,customers_copy!$A$1:$E$22,2,0) -> Kaveri Foods | M12: =VLOOKUP(C12,customers_copy!$A$1:$E$22,4,0) -> Wholesale | V12: 35910
A13: O1012 | B13: 46058 | C13: C012 | D13: Keyboard | E13: Electronics | F13: East | G13: 20 | H13: 1800 | I13: 0.06 | J13: =(G13*H13)*(1-I13) -> 33840 | K13: =G13*H13*I13 -> 2160 | L13: =VLOOKUP(C13,customers_copy!$A$1:$E$22,2,0) -> Lotus Retail | M13: =VLOOKUP(C13,customers_copy!$A$1:$E$22,4,0) -> Retail | V13: 44100
A14: O1013 | B14: 46061 | C14: C013 | D14: Laptop Stand | E14: Electronics | F14: North | G14: 10 | H14: 1250 | I14: 0.05 | J14: =(G14*H14)*(1-I14) -> 11875 | K14: =G14*H14*I14 -> 625 | L14: =VLOOKUP(C14,customers_copy!$A$1:$E$22,2,0) -> Metro Bazaar | M14: =VLOOKUP(C14,customers_copy!$A$1:$E$22,4,0) -> Retail
A15: O1014 | B15: 46064 | C15: C014 | D15: Monitor | E15: Electronics | F15: West | G15: 8 | H15: 14500 | I15: 0.15 | J15: =(G15*H15)*(1-I15) -> 98600 | K15: =G15*H15*I15 -> 17400 | L15: =VLOOKUP(C15,customers_copy!$A$1:$E$22,2,0) -> Nova Wholesale | M15: =VLOOKUP(C15,customers_copy!$A$1:$E$22,4,0) -> Wholesale | V15: 46368
A16: O1015 | B16: 46067 | C16: C015 | D16: Desk | E16: Furniture | F16: South | G16: 3 | H16: 12000 | I16: 0.05 | J16: =(G16*H16)*(1-I16) -> 34200 | K16: =G16*H16*I16 -> 1800 | L16: =VLOOKUP(C16,customers_copy!$A$1:$E$22,2,0) -> Orchid Cafe | M16: =VLOOKUP(C16,customers_copy!$A$1:$E$22,4,0) -> Food Service
A17: O1016 | B17: 46070 | C17: C016 | D17: Mouse | E17: Electronics | F17: East | G17: 30 | H17: 750 | I17: 0.02 | J17: =(G17*H17)*(1-I17) -> 22050 | K17: =G17*H17*I17 -> 450 | L17: =VLOOKUP(C17,customers_copy!$A$1:$E$22,2,0) -> Prime Grocers | M17: =VLOOKUP(C17,customers_copy!$A$1:$E$22,4,0) -> Retail | V17: 11875
A18: O1017 | B18: 46073 | C18: C017 | D18: Webcam | E18: Electronics | F18: North | G18: 9 | H18: 3200 | I18: 0.07 | J18: =(G18*H18)*(1-I18) -> 26784 | K18: =G18*H18*I18 -> 2016 | L18: =VLOOKUP(C18,customers_copy!$A$1:$E$22,2,0) -> QuickBuy | M18: =VLOOKUP(C18,customers_copy!$A$1:$E$22,4,0) -> Retail | V18: 98600
A19: O1018 | B19: 46076 | C19: C018 | D19: Printer | E19: Electronics | F19: West | G19: 6 | H19: 9800 | I19: 0.1 | J19: =(G19*H19)*(1-I19) -> 52920 | K19: =G19*H19*I19 -> 5880 | L19: =VLOOKUP(C19,customers_copy!$A$1:$E$22,2,0) -> Royal Foods | M19: =VLOOKUP(C19,customers_copy!$A$1:$E$22,4,0) -> Wholesale | V19: 34200
A20: O1019 | B20: 46078 | C20: C019 | D20: Headset | E20: Electronics | F20: South | G20: 16 | H20: 2100 | I20: 0.05 | J20: =(G20*H20)*(1-I20) -> 31920 | K20: =G20*H20*I20 -> 1680 | L20: =VLOOKUP(C20,customers_copy!$A$1:$E$22,2,0) -> Sunrise Mart | M20: =VLOOKUP(C20,customers_copy!$A$1:$E$22,4,0) -> Retail | V20: 22050
A21: O1020 | B21: 46080 | C21: C020 | D21: Desk Lamp | E21: Furniture | F21: East | G21: 11 | H21: 1650 | I21: 0.03 | J21: =(G21*H21)*(1-I21) -> 17605.5 | K21: =G21*H21*I21 -> 544.5 | L21: =VLOOKUP(C21,customers_copy!$A$1:$E$22,2,0) -> TrueValue | M21: =VLOOKUP(C21,customers_copy!$A$1:$E$22,4,0) -> Wholesale
A22: O1021 | B22: 46083 | C22: C001 | D22: Monitor | E22: Electronics | F22: North | G22: 7 | H22: 14500 | I22: 0.1 | J22: =(G22*H22)*(1-I22) -> 91350 | K22: =G22*H22*I22 -> 10150 | L22: =VLOOKUP(C22,customers_copy!$A$1:$E$22,2,0) -> Aarav Retail | M22: =VLOOKUP(C22,customers_copy!$A$1:$E$22,4,0) -> Retail
A23: O1022 | B23: 46086 | C23: C003 | D23: Office Chair | E23: Furniture | F23: West | G23: 5 | H23: 7200 | I23: 0.08 | J23: =(G23*H23)*(1-I23) -> 33120 | K23: =G23*H23*I23 -> 2880 | L23: =VLOOKUP(C23,customers_copy!$A$1:$E$22,2,0) -> Crest Foods | M23: =VLOOKUP(C23,customers_copy!$A$1:$E$22,4,0) -> Wholesale
A24: O1023 | B24: 46089 | C24: C002 | D24: Keyboard | E24: Electronics | F24: South | G24: 22 | H24: 1800 | I24: 0.05 | J24: =(G24*H24)*(1-I24) -> 37620 | K24: =G24*H24*I24 -> 1980 | L24: =VLOOKUP(C24,customers_copy!$A$1:$E$22,2,0) -> BlueMart | M24: =VLOOKUP(C24,customers_copy!$A$1:$E$22,4,0) -> Retail
A25: O1024 | B25: 46092 | C25: C005 | D25: Laptop Stand | E25: Electronics | F25: South | G25: 13 | H25: 1250 | I25: 0.04 | J25: =(G25*H25)*(1-I25) -> 15600 | K25: =G25*H25*I25 -> 650 | L25: =VLOOKUP(C25,customers_copy!$A$1:$E$22,2,0) -> Elite Supplies | M25: =VLOOKUP(C25,customers_copy!$A$1:$E$22,4,0) -> Wholesale
A26: O1025 | B26: 46095 | C26: C004 | D26: Printer | E26: Electronics | F26: North | G26: 4 | H26: 9800 | I26: 0.09 | J26: =(G26*H26)*(1-I26) -> 35672 | K26: =G26*H26*I26 -> 3528 | L26: =VLOOKUP(C26,customers_copy!$A$1:$E$22,2,0) -> Delta Stores | M26: =VLOOKUP(C26,customers_copy!$A$1:$E$22,4,0) -> Retail
A27: O1026 | B27: 46098 | C27: C006 | D27: Desk Lamp | E27: Furniture | F27: East | G27: 17 | H27: 1650 | I27: 0.03 | J27: =(G27*H27)*(1-I27) -> 27208.5 | K27: =G27*H27*I27 -> 841.5 | L27: =VLOOKUP(C27,customers_copy!$A$1:$E$22,2,0) -> Fresh Basket | M27: =VLOOKUP(C27,customers_copy!$A$1:$E$22,4,0) -> Retail
A28: O1027 | B28: 46101 | C28: C007 | D28: Mouse | E28: Electronics | F28: West | G28: 28 | H28: 750 | I28: 0.02 | J28: =(G28*H28)*(1-I28) -> 20580 | K28: =G28*H28*I28 -> 420 | L28: =VLOOKUP(C28,customers_copy!$A$1:$E$22,2,0) -> Green Valley | M28: =VLOOKUP(C28,customers_copy!$A$1:$E$22,4,0) -> Retail
A29: O1028 | B29: 46104 | C29: C008 | D29: Webcam | E29: Electronics | F29: South | G29: 10 | H29: 3200 | I29: 0.06 | J29: =(G29*H29)*(1-I29) -> 30080 | K29: =G29*H29*I29 -> 1920 | L29: =VLOOKUP(C29,customers_copy!$A$1:$E$22,2,0) -> Horizon Cafe | M29: =VLOOKUP(C29,customers_copy!$A$1:$E$22,4,0) -> Food Service
A30: O1029 | B30: 46107 | C30: C009 | D30: Monitor | E30: Electronics | F30: North | G30: 6 | H30: 14500 | I30: 0.11 | J30: =(G30*H30)*(1-I30) -> 77430 | K30: =G30*H30*I30 -> 9570 | L30: =VLOOKUP(C30,customers_copy!$A$1:$E$22,2,0) -> Ivy Traders | M30: =VLOOKUP(C30,customers_copy!$A$1:$E$22,4,0) -> Wholesale
A31: O1030 | B31: 46110 | C31: C010 | D31: Headset | E31: Electronics | F31: West | G31: 21 | H31: 2100 | I31: 0.05 | J31: =(G31*H31)*(1-I31) -> 41895 | K31: =G31*H31*I31 -> 2205 | L31: =VLOOKUP(C31,customers_copy!$A$1:$E$22,2,0) -> Jupiter Mart | M31: =VLOOKUP(C31,customers_copy!$A$1:$E$22,4,0) -> Retail
A32: O1031 | B32: 46114 | C32: C011 | D32: Printer | E32: Electronics | F32: South | G32: 3 | H32: 9800 | I32: 0.08 | J32: =(G32*H32)*(1-I32) -> 27048 | K32: =G32*H32*I32 -> 2352 | L32: =VLOOKUP(C32,customers_copy!$A$1:$E$22,2,0) -> Kaveri Foods | M32: =VLOOKUP(C32,customers_copy!$A$1:$E$22,4,0) -> Wholesale
... A41: O1040 | B41: 46141 | C41: C020 | D41: Webcam | E41: Electronics | F41: East | G41: 14 | H41: 3200 | I41: 0.06 | J41: =(G41*H41)*(1-I41) -> 42112 | K41: =G41*H41*I41 -> 2688 | L41: =VLOOKUP(C41,customers_copy!$A$1:$E$22,2,0) -> TrueValue | M41: =VLOOKUP(C41,customers_copy!$A$1:$E$22,4,0) -> Wholesale

Sheet salestasks3
A1: filtered based on electronics and sales amount largest to smallest
A2: Order ID | B2: Order Date | C2: Customer ID | D2: Product | E2: Category | F2: Region | G2: Units | H2: Unit Price | I2: Discount | J2: sales_amount | K2: discount_amount | L2: customer name | M2: segment
A3: O1004 | B3: 46034 | C3: C005 | D3: Monitor | E3: Electronics | F3: South | G3: 9 | H3: 14500 | I3: 0.12 | J3: =(G3*H3)*(1-I3) -> 114840 | K3: =G3*H3*I3 -> 15660 | L3: =VLOOKUP(C3,customers_copy!$A$1:$E$22,2,0) -> Elite Supplies | M3: =VLOOKUP(C3,customers_copy!$A$1:$E$22,4,0) -> Wholesale
A4: O1014 | B4: 46064 | C4: C014 | D4: Monitor | E4: Electronics | F4: West | G4: 8 | H4: 14500 | I4: 0.15 | J4: =(G4*H4)*(1-I4) -> 98600 | K4: =G4*H4*I4 -> 17400 | L4: =VLOOKUP(C4,customers_copy!$A$1:$E$22,2,0) -> Nova Wholesale | M4: =VLOOKUP(C4,customers_copy!$A$1:$E$22,4,0) -> Wholesale
A5: O1021 | B5: 46083 | C5: C001 | D5: Monitor | E5: Electronics | F5: North | G5: 7 | H5: 14500 | I5: 0.1 | J5: =(G5*H5)*(1-I5) -> 91350 | K5: =G5*H5*I5 -> 10150 | L5: =VLOOKUP(C5,customers_copy!$A$1:$E$22,2,0) -> Aarav Retail | M5: =VLOOKUP(C5,customers_copy!$A$1:$E$22,4,0) -> Retail
A6: O1029 | B6: 46107 | C6: C009 | D6: Monitor | E6: Electronics | F6: North | G6: 6 | H6: 14500 | I6: 0.11 | J6: =(G6*H6)*(1-I6) -> 77430 | K6: =G6*H6*I6 -> 9570 | L6: =VLOOKUP(C6,customers_copy!$A$1:$E$22,2,0) -> Ivy Traders | M6: =VLOOKUP(C6,customers_copy!$A$1:$E$22,4,0) -> Wholesale
A7: O1033 | B7: 46120 | C7: C013 | D7: Desk | E7: Furniture | F7: North | G7: 5 | H7: 12000 | I7: 0.05 | J7: =(G7*H7)*(1-I7) -> 57000 | K7: =G7*H7*I7 -> 3000 | L7: =VLOOKUP(C7,customers_copy!$A$1:$E$22,2,0) -> Metro Bazaar | M7: =VLOOKUP(C7,customers_copy!$A$1:$E$22,4,0) -> Retail
A8: O1032 | B8: 46117 | C8: C012 | D8: Office Chair | E8: Furniture | F8: East | G8: 8 | H8: 7200 | I8: 0.07 | J8: =(G8*H8)*(1-I8) -> 53568 | K8: =G8*H8*I8 -> 4032 | L8: =VLOOKUP(C8,customers_copy!$A$1:$E$22,2,0) -> Lotus Retail | M8: =VLOOKUP(C8,customers_copy!$A$1:$E$22,4,0) -> Retail
A9: O1018 | B9: 46076 | C9: C018 | D9: Printer | E9: Electronics | F9: West | G9: 6 | H9: 9800 | I9: 0.1 | J9: =(G9*H9)*(1-I9) -> 52920 | K9: =G9*H9*I9 -> 5880 | L9: =VLOOKUP(C9,customers_copy!$A$1:$E$22,2,0) -> Royal Foods | M9: =VLOOKUP(C9,customers_copy!$A$1:$E$22,4,0) -> Wholesale
A10: O1036 | B10: 46129 | C10: C016 | D10: Monitor | E10: Electronics | F10: East | G10: 4 | H10: 14500 | I10: 0.1 | J10: =(G10*H10)*(1-I10) -> 52200 | K10: =G10*H10*I10 -> 5800 | L10: =VLOOKUP(C10,customers_copy!$A$1:$E$22,2,0) -> Prime Grocers | M10: =VLOOKUP(C10,customers_copy!$A$1:$E$22,4,0) -> Retail
A11: O1011 | B11: 46055 | C11: C011 | D11: Office Chair | E11: Furniture | F11: South | G11: 7 | H11: 7200 | I11: 0.08 | J11: =(G11*H11)*(1-I11) -> 46368 | K11: =G11*H11*I11 -> 4032 | L11: =VLOOKUP(C11,customers_copy!$A$1:$E$22,2,0) -> Kaveri Foods | M11: =VLOOKUP(C11,customers_copy!$A$1:$E$22,4,0) -> Wholesale
A12: O1005 | B12: 46037 | C12: C004 | D12: Desk | E12: Furniture | F12: North | G12: 4 | H12: 12000 | I12: 0.05 | J12: =(G12*H12)*(1-I12) -> 45600 | K12: =G12*H12*I12 -> 2400 | L12: =VLOOKUP(C12,customers_copy!$A$1:$E$22,2,0) -> Delta Stores | M12: =VLOOKUP(C12,customers_copy!$A$1:$E$22,4,0) -> Retail
A13: O1039 | B13: 46138 | C13: C019 | D13: Printer | E13: Electronics | F13: South | G13: 5 | H13: 9800 | I13: 0.08 | J13: =(G13*H13)*(1-I13) -> 45080 | K13: =G13*H13*I13 -> 3920 | L13: =VLOOKUP(C13,customers_copy!$A$1:$E$22,2,0) -> Sunrise Mart | M13: =VLOOKUP(C13,customers_copy!$A$1:$E$22,4,0) -> Retail
A14: O1009 | B14: 46048 | C14: C009 | D14: Printer | E14: Electronics | F14: North | G14: 5 | H14: 9800 | I14: 0.1 | J14: =(G14*H14)*(1-I14) -> 44100 | K14: =G14*H14*I14 -> 4900 | L14: =VLOOKUP(C14,customers_copy!$A$1:$E$22,2,0) -> Ivy Traders | M14: =VLOOKUP(C14,customers_copy!$A$1:$E$22,4,0) -> Wholesale
A15: O1040 | B15: 46141 | C15: C020 | D15: Webcam | E15: Electronics | F15: East | G15: 14 | H15: 3200 | I15: 0.06 | J15: =(G15*H15)*(1-I15) -> 42112 | K15: =G15*H15*I15 -> 2688 | L15: =VLOOKUP(C15,customers_copy!$A$1:$E$22,2,0) -> TrueValue | M15: =VLOOKUP(C15,customers_copy!$A$1:$E$22,4,0) -> Wholesale
A16: O1030 | B16: 46110 | C16: C010 | D16: Headset | E16: Electronics | F16: West | G16: 21 | H16: 2100 | I16: 0.05 | J16: =(G16*H16)*(1-I16) -> 41895 | K16: =G16*H16*I16 -> 2205 | L16: =VLOOKUP(C16,customers_copy!$A$1:$E$22,2,0) -> Jupiter Mart | M16: =VLOOKUP(C16,customers_copy!$A$1:$E$22,4,0) -> Retail | Q16: PivotTable: Product in Rows; Sales Amount in Values as SUM; Region in Filters. Test North.
A17: O1003 | B17: 46031 | C17: C002 | D17: Office Chair | E17: Furniture | F17: South | G17: 6 | H17: 7200 | I17: 0.08 | J17: =(G17*H17)*(1-I17) -> 39744 | K17: =G17*H17*I17 -> 3456 | L17: =VLOOKUP(C17,customers_copy!$A$1:$E$22,2,0) -> BlueMart | M17: =VLOOKUP(C17,customers_copy!$A$1:$E$22,4,0) -> Retail
A18: O1023 | B18: 46089 | C18: C002 | D18: Keyboard | E18: Electronics | F18: South | G18: 22 | H18: 1800 | I18: 0.05 | J18: =(G18*H18)*(1-I18) -> 37620 | K18: =G18*H18*I18 -> 1980 | L18: =VLOOKUP(C18,customers_copy!$A$1:$E$22,2,0) -> BlueMart | M18: =VLOOKUP(C18,customers_copy!$A$1:$E$22,4,0) -> Retail | Q18: Region | R18: North
A19: O1008 | B19: 46045 | C19: C008 | D19: Headset | E19: Electronics | F19: South | G19: 18 | H19: 2100 | I19: 0.05 | J19: =(G19*H19)*(1-I19) -> 35910 | K19: =G19*H19*I19 -> 1890 | L19: =VLOOKUP(C19,customers_copy!$A$1:$E$22,2,0) -> Horizon Cafe | M19: =VLOOKUP(C19,customers_copy!$A$1:$E$22,4,0) -> Food Service
A20: O1007 | B20: 46042 | C20: C007 | D20: Webcam | E20: Electronics | F20: West | G20: 12 | H20: 3200 | I20: 0.07 | J20: =(G20*H20)*(1-I20) -> 35712 | K20: =G20*H20*I20 -> 2688 | L20: =VLOOKUP(C20,customers_copy!$A$1:$E$22,2,0) -> Green Valley | M20: =VLOOKUP(C20,customers_copy!$A$1:$E$22,4,0) -> Retail | Q20: Row Labels | R20: Sum of sales_amount
A21: O1025 | B21: 46095 | C21: C004 | D21: Printer | E21: Electronics | F21: North | G21: 4 | H21: 9800 | I21: 0.09 | J21: =(G21*H21)*(1-I21) -> 35672 | K21: =G21*H21*I21 -> 3528 | L21: =VLOOKUP(C21,customers_copy!$A$1:$E$22,2,0) -> Delta Stores | M21: =VLOOKUP(C21,customers_copy!$A$1:$E$22,4,0) -> Retail | Q21: Desk | R21: 102600
A22: O1015 | B22: 46067 | C22: C015 | D22: Desk | E22: Furniture | F22: South | G22: 3 | H22: 12000 | I22: 0.05 | J22: =(G22*H22)*(1-I22) -> 34200 | K22: =G22*H22*I22 -> 1800 | L22: =VLOOKUP(C22,customers_copy!$A$1:$E$22,2,0) -> Orchid Cafe | M22: =VLOOKUP(C22,customers_copy!$A$1:$E$22,4,0) -> Food Service | Q22: Laptop Stand | R22: 40375
A23: O1012 | B23: 46058 | C23: C012 | D23: Keyboard | E23: Electronics | F23: East | G23: 20 | H23: 1800 | I23: 0.06 | J23: =(G23*H23)*(1-I23) -> 33840 | K23: =G23*H23*I23 -> 2160 | L23: =VLOOKUP(C23,customers_copy!$A$1:$E$22,2,0) -> Lotus Retail | M23: =VLOOKUP(C23,customers_copy!$A$1:$E$22,4,0) -> Retail | Q23: Monitor | R23: 168780
A24: O1022 | B24: 46086 | C24: C003 | D24: Office Chair | E24: Furniture | F24: West | G24: 5 | H24: 7200 | I24: 0.08 | J24: =(G24*H24)*(1-I24) -> 33120 | K24: =G24*H24*I24 -> 2880 | L24: =VLOOKUP(C24,customers_copy!$A$1:$E$22,2,0) -> Crest Foods | M24: =VLOOKUP(C24,customers_copy!$A$1:$E$22,4,0) -> Wholesale | Q24: Printer | R24: 79772
A25: O1034 | B25: 46123 | C25: C014 | D25: Keyboard | E25: Electronics | F25: West | G25: 19 | H25: 1800 | I25: 0.04 | J25: =(G25*H25)*(1-I25) -> 32832 | K25: =G25*H25*I25 -> 1368 | L25: =VLOOKUP(C25,customers_copy!$A$1:$E$22,2,0) -> Nova Wholesale | M25: =VLOOKUP(C25,customers_copy!$A$1:$E$22,4,0) -> Wholesale | Q25: Webcam | R25: 26784
A26: O1019 | B26: 46078 | C26: C019 | D26: Headset | E26: Electronics | F26: South | G26: 16 | H26: 2100 | I26: 0.05 | J26: =(G26*H26)*(1-I26) -> 31920 | K26: =G26*H26*I26 -> 1680 | L26: =VLOOKUP(C26,customers_copy!$A$1:$E$22,2,0) -> Sunrise Mart | M26: =VLOOKUP(C26,customers_copy!$A$1:$E$22,4,0) -> Retail | Q26: Grand Total | R26: 418311
A27: O1028 | B27: 46104 | C27: C008 | D27: Webcam | E27: Electronics | F27: South | G27: 10 | H27: 3200 | I27: 0.06 | J27: =(G27*H27)*(1-I27) -> 30080 | K27: =G27*H27*I27 -> 1920 | L27: =VLOOKUP(C27,customers_copy!$A$1:$E$22,2,0) -> Horizon Cafe | M27: =VLOOKUP(C27,customers_copy!$A$1:$E$22,4,0) -> Food Service
A28: O1026 | B28: 46098 | C28: C006 | D28: Desk Lamp | E28: Furniture | F28: East | G28: 17 | H28: 1650 | I28: 0.03 | J28: =(G28*H28)*(1-I28) -> 27208.5 | K28: =G28*H28*I28 -> 841.5 | L28: =VLOOKUP(C28,customers_copy!$A$1:$E$22,2,0) -> Fresh Basket | M28: =VLOOKUP(C28,customers_copy!$A$1:$E$22,4,0) -> Retail
A29: O1031 | B29: 46114 | C29: C011 | D29: Printer | E29: Electronics | F29: South | G29: 3 | H29: 9800 | I29: 0.08 | J29: =(G29*H29)*(1-I29) -> 27048 | K29: =G29*H29*I29 -> 2352 | L29: =VLOOKUP(C29,customers_copy!$A$1:$E$22,2,0) -> Kaveri Foods | M29: =VLOOKUP(C29,customers_copy!$A$1:$E$22,4,0) -> Wholesale
A30: O1017 | B30: 46073 | C30: C017 | D30: Webcam | E30: Electronics | F30: North | G30: 9 | H30: 3200 | I30: 0.07 | J30: =(G30*H30)*(1-I30) -> 26784 | K30: =G30*H30*I30 -> 2016 | L30: =VLOOKUP(C30,customers_copy!$A$1:$E$22,2,0) -> QuickBuy | M30: =VLOOKUP(C30,customers_copy!$A$1:$E$22,4,0) -> Retail
A31: O1002 | B31: 46029 | C31: C003 | D31: Keyboard | E31: Electronics | F31: West | G31: 15 | H31: 1800 | I31: 0.1 | J31: =(G31*H31)*(1-I31) -> 24300 | K31: =G31*H31*I31 -> 2700 | L31: =VLOOKUP(C31,customers_copy!$A$1:$E$22,2,0) -> Crest Foods | M31: =VLOOKUP(C31,customers_copy!$A$1:$E$22,4,0) -> Wholesale | Q31: PivotTable: Category in Rows; Sales Amount in Values as AVERAGE. Compare categories.
A32: O1010 | B32: 46050 | C32: C010 | D32: Desk Lamp | E32: Furniture | F32: West | G32: 14 | H32: 1650 | I32: 0.03 | J32: =(G32*H32)*(1-I32) -> 22407 | K32: =G32*H32*I32 -> 693 | L32: =VLOOKUP(C32,customers_copy!$A$1:$E$22,2,0) -> Jupiter Mart | M32: =VLOOKUP(C32,customers_copy!$A$1:$E$22,4,0) -> Retail
A33: O1016 | B33: 46070 | C33: C016 | D33: Mouse | E33: Electronics | F33: East | G33: 30 | H33: 750 | I33: 0.02 | J33: =(G33*H33)*(1-I33) -> 22050 | K33: =G33*H33*I33 -> 450 | L33: =VLOOKUP(C33,customers_copy!$A$1:$E$22,2,0) -> Prime Grocers | M33: =VLOOKUP(C33,customers_copy!$A$1:$E$22,4,0) -> Retail
A34: O1038 | B34: 46135 | C34: C018 | D34: Desk Lamp | E34: Furniture | F34: West | G34: 13 | H34: 1650 | I34: 0.03 | J34: =(G34*H34)*(1-I34) -> 20806.5 | K34: =G34*H34*I34 -> 643.5 | L34: =VLOOKUP(C34,customers_copy!$A$1:$E$22,2,0) -> Royal Foods | M34: =VLOOKUP(C34,customers_copy!$A$1:$E$22,4,0) -> Wholesale
A35: O1027 | B35: 46101 | C35: C007 | D35: Mouse | E35: Electronics | F35: West | G35: 28 | H35: 750 | I35: 0.02 | J35: =(G35*H35)*(1-I35) -> 20580 | K35: =G35*H35*I35 -> 420 | L35: =VLOOKUP(C35,customers_copy!$A$1:$E$22,2,0) -> Green Valley | M35: =VLOOKUP(C35,customers_copy!$A$1:$E$22,4,0) -> Retail
A36: O1035 | B36: 46126 | C36: C015 | D36: Mouse | E36: Electronics | F36: South | G36: 26 | H36: 750 | I36: 0.02 | J36: =(G36*H36)*(1-I36) -> 19110 | K36: =G36*H36*I36 -> 390 | L36: =VLOOKUP(C36,customers_copy!$A$1:$E$22,2,0) -> Orchid Cafe | M36: =VLOOKUP(C36,customers_copy!$A$1:$E$22,4,0) -> Food Service | Q36: Row Labels | R36: Average of sales_amount
A37: O1037 | B37: 46132 | C37: C017 | D37: Laptop Stand | E37: Electronics | F37: North | G37: 16 | H37: 1250 | I37: 0.05 | J37: =(G37*H37)*(1-I37) -> 19000 | K37: =G37*H37*I37 -> 1000 | L37: =VLOOKUP(C37,customers_copy!$A$1:$E$22,2,0) -> QuickBuy | M37: =VLOOKUP(C37,customers_copy!$A$1:$E$22,4,0) -> Retail | Q37: Electronics | R37: 39610.69
A38: O1006 | B38: 46040 | C38: C006 | D38: Mouse | E38: Electronics | F38: East | G38: 25 | H38: 750 | I38: 0 | J38: =(G38*H38)*(1-I38) -> 18750 | K38: =G38*H38*I38 -> 0 | L38: =VLOOKUP(C38,customers_copy!$A$1:$E$22,2,0) -> Fresh Basket | M38: =VLOOKUP(C38,customers_copy!$A$1:$E$22,4,0) -> Retail | Q38: Furniture | R38: 36147.955
A39: O1020 | B39: 46080 | C39: C020 | D39: Desk Lamp | E39: Furniture | F39: East | G39: 11 | H39: 1650 | I39: 0.03 | J39: =(G39*H39)*(1-I39) -> 17605.5 | K39: =G39*H39*I39 -> 544.5 | L39: =VLOOKUP(C39,customers_copy!$A$1:$E$22,2,0) -> TrueValue | M39: =VLOOKUP(C39,customers_copy!$A$1:$E$22,4,0) -> Wholesale | Q39: Grand Total | R39: 38658.438
A40: O1024 | B40: 46092 | C40: C005 | D40: Laptop Stand | E40: Electronics | F40: South | G40: 13 | H40: 1250 | I40: 0.04 | J40: =(G40*H40)*(1-I40) -> 15600 | K40: =G40*H40*I40 -> 650 | L40: =VLOOKUP(C40,customers_copy!$A$1:$E$22,2,0) -> Elite Supplies | M40: =VLOOKUP(C40,customers_copy!$A$1:$E$22,4,0) -> Wholesale
...

Sheet pivot and charts1
A1: PivotTable hierarchy: Region in Rows, Category under Region, Sales Amount in Values. | O1: Create a column chart for Sales Amount by Product using a summarized table.
O2: Row Labels | P2: Sum of sales_amount
O3: Desk | P3: 136800
O4: Desk Lamp | P4: 88027.5
A5: Row Labels | B5: Sum of sales_amount | O5: Headset | P5: 109725
A6: East | B6: 267334 | O6: Keyboard | P6: 128592
A7: Electronics | B7: 168952 | O7: Laptop Stand | P7: 55975
A8: Furniture | B8: 98382 | O8: Monitor | P8: 434420
A9: North | B9: 418311 | O9: Mouse | P9: 80490
A10: Electronics | B10: 315711 | O10: Office Chair | P10: 172800
A11: Furniture | B11: 102600 | O11: Printer | P11: 204820
A12: South | B12: 477520 | O12: Webcam | P12: 134688
A13: Electronics | B13: 357208 | O13: Grand Total | P13: 1546337.5
A14: Furniture | B14: 120312
A15: West | B15: 383172.5
A16: Electronics | B16: 306839
A17: Furniture | B17: 76333.5
A18: Grand Total | B18: 1546337.5
A22: pivot table showing highest sum of sales by region | F22: Create a PivotChart from Region Sales. Add a meaningful title and data labels.
A26: Row Labels | B26: Sum of sales_amount
A27: East | B27: 267334
A28: North | B28: 418311
A29: South | B29: 477520
A30: West | B30: 383172.5
A31: Grand Total | B31: 1546337.5
B41: Create a line chart for monthly Sales Amount.
B43: Row Labels | C43: Sum of sales_amount
B44: Jan | C44: 390863
B45: Feb | C45: 376162.5
B46: Mar | C46: 410555.5
B47: Apr | C47: 368756.5
B48: Grand Total | C48: 1546337.5

Sheet charts2
A1: Create a pie chart for Sales Amount by Region using the four region totals.
A4: Row Labels | B4: Sum of sales_amount
A5: East | B5: 267334
A6: North | B6: 418311
A7: South | B7: 477520
A8: West | B8: 383172.5
A9: Grand Total | B9: 1546337.5
A21: Create a scatter chart with Units on X and Sales Amount on Y. Add axis titles. | N21: Create a combo chart with monthly Sales Amount as columns and Average Discount as a line on the secondary Y-axis.
N24: Row Labels | O24: Average of Discount | P24: Sum of sales_amount
N25: Jan | O25: 0.065 | P25: 390863
N26: Feb | O26: 0.066 | P26: 376162.5
N27: Mar | O27: 0.063 | P27: 410555.5
N28: Apr | O28: 0.058 | P28: 368756.5
N29: Grand Total | O29: 0.063 | P29: 1546337.5

Sheet sales_tasks2
B2: Create a horizontal Sales Band table: 0=Low, 10000=Medium, 25000=High, 50000=Very High. Use HLOOKUP with approximate match on selected Sales Amounts.
B3: 0 | C3: 10000 | D3: 25000 | E3: 50000 | H3: Range | I3: sales_amount
B4: LOW | C4: MEDIUM | D4: HIGH | E4: VERY HIGH | H4: =HLOOKUP(I4,$B$3:$E$4,2,1) -> LOW | I4: 9500
H5: =HLOOKUP(I5,$B$3:$E$4,2,1) -> MEDIUM | I5: 24300
H6: =HLOOKUP(I6,$B$3:$E$4,2,1) -> HIGH | I6: 39744
H7: =HLOOKUP(I7,$B$3:$E$4,2,1) -> VERY HIGH | I7: 114840
H8: =HLOOKUP(I8,$B$3:$E$4,2,1) -> HIGH | I8: 45600
H9: =HLOOKUP(I9,$B$3:$E$4,2,1) -> MEDIUM | I9: 18750
H10: =HLOOKUP(I10,$B$3:$E$4,2,1) -> HIGH | I10: 35712
H11: =HLOOKUP(I11,$B$3:$E$4,2,1) -> HIGH | I11: 35910
H12: =HLOOKUP(I12,$B$3:$E$4,2,1) -> HIGH | I12: 44100
H13: =HLOOKUP(I13,$B$3:$E$4,2,1) -> MEDIUM | I13: 22407
H14: =HLOOKUP(I14,$B$3:$E$4,2,1) -> HIGH | I14: 46368
H15: =HLOOKUP(I15,$B$3:$E$4,2,1) -> HIGH | I15: 33840
H16: =HLOOKUP(I16,$B$3:$E$4,2,1) -> MEDIUM | I16: 11875
B17: exact - match vs approximate-match | H17: =HLOOKUP(I17,$B$3:$E$4,2,1) -> VERY HIGH | I17: 98600
B18: EXACT-MATCH | H18: =HLOOKUP(I18,$B$3:$E$4,2,1) -> HIGH | I18: 34200
B19: Exact Match — FALSE or 0 | H19: =HLOOKUP(I19,$B$3:$E$4,2,1) -> MEDIUM | I19: 22050
B20: Finds only the exact value you requested. | H20: =HLOOKUP(I20,$B$3:$E$4,2,1) -> VERY HIGH | I20: 52920
B21: Example: Search for employee ID 104. Excel looks for ID 104, not 103 or 105.
B23: Approximate Match — TRUE or 1
B25: Finds the closest suitable value.
B26: For VLOOKUP,HLOOKUP this normally means the largest value less than or equal to your lookup value, provided the first column is sorted in ascending order.
B28: XLOOKUP | C28: syntax
B29: =xlookup(lookup_value, lookup_array,return_array,[ if not found],[match mode],[search mode])
C33: Order ID | D33: Order Status
C34: ORD001 | D34: pending
C35: ORD002
C36: ORD003
C37: ORD004
C38: ORD005
C39: ORD006
C40: ORD007
C41: ORD008
C42: ORD009
C43: ORD010

Sheet customer_answers
A1: Customer ID | B1: Customer Name | C1: Region | D1: Segment | E1: City
A2: C001 | B2: Aarav Retail | C2: North | D2: Retail | E2: Hyderabad
A3: C002 | B3: BlueMart | C3: South | D3: Retail | E3: Chennai
A4: C003 | B4: Crest Foods | C4: West | D4: Wholesale | E4: Mumbai
A5: C004 | B5: Delta Stores | C5: North | D5: Retail | E5: Delhi
A6: C005 | B6: Elite Supplies | C6: South | D6: Wholesale | E6: Bengaluru
A7: C006 | B7: Fresh Basket | C7: East | D7: Retail | E7: Kolkata
A8: C007 | B8: Green Valley | C8: West | D8: Retail | E8: Pune
A9: C008 | B9: Horizon Cafe | C9: South | D9: Food Service | E9: Chennai
A10: C009 | B10: Ivy Traders | C10: North | D10: Wholesale | E10: Delhi
A11: C010 | B11: Jupiter Mart | C11: West | D11: Retail | E11: Pune
A12: C011 | B12: Kaveri Foods | C12: South | D12: Wholesale | E12: Hyderabad
... A21: C020 | B21: TrueValue | C21: East | D21: Wholesale | E21: Kolkata
